Workbook
Name Loai_Thong_Tin: 'Master Data'!$I$8:$I$9
Name Muc_Tieu: 'Master Data'!$AL$5:$AL$9
Name To_Chuc: 'Master Data'!$D$5:$D$20
Name Trang_Thai: 'Master Data'!$I$5:$I$7

Sheet Dự đoán giá nhà
A1: Năm | B1: Giá trị đầu kỳ (VNĐ) | C1: Lạm phát dự kiến (%) | D1: Giá trị dự kiến (VNĐ) | E1: Lạm phát thực tế (%) | F1: Giá trị thực tế (VNĐ) | G1: STT
A2: 2025 | B2: 2000000000 | C2: 3.25 | D2: =$B2*(1+C2/100) -> 2065000000 | F2: =IF(E2="","",$B2*(1+E2/100)) | G2: 1
A3: 2026 | B3: =IF(F2<>"",F2,D2) -> 2065000000 | C3: 3 | D3: =$B3*(1+C3/100) -> 2126950000 | F3: =IF(E3="","",$B3*(1+E3/100)) | G3: 2
A4: 2027 | B4: =IF(F3<>"",F3,D3) -> 2126950000 | C4: 2.4 | D4: =$B4*(1+C4/100) -> 2177996800 | F4: =IF(E4="","",$B4*(1+E4/100)) | G4: 3
A5: 2028 | B5: =IF(F4<>"",F4,D4) -> 2177996800 | C5: 4 | D5: =$B5*(1+C5/100) -> 2265116672 | F5: =IF(E5="","",$B5*(1+E5/100)) | G5: 4
A6: 2029 | B6: =IF(F5<>"",F5,D5) -> 2265116672 | C6: 4 | D6: =$B6*(1+C6/100) -> 2.3557213e+09 | F6: =IF(E6="","",$B6*(1+E6/100)) | G6: 5
A7: 2030 | B7: =IF(F6<>"",F6,D6) -> 2.3557213e+09 | C7: 4 | D7: =$B7*(1+C7/100) -> 2.4499502e+09 | F7: =IF(E7="","",$B7*(1+E7/100)) | G7: 6
A8: 2031 | B8: =IF(F7<>"",F7,D7) -> 2.4499502e+09 | C8: 4 | D8: =$B8*(1+C8/100) -> 2.5479482e+09 | F8: =IF(E8="","",$B8*(1+E8/100)) | G8: 7
A9: 2032 | B9: =IF(F8<>"",F8,D8) -> 2.5479482e+09 | C9: 4 | D9: =$B9*(1+C9/100) -> 2.6498661e+09 | F9: =IF(E9="","",$B9*(1+E9/100)) | G9: 8
A10: 2033 | B10: =IF(F9<>"",F9,D9) -> 2.6498661e+09 | C10: 4 | D10: =$B10*(1+C10/100) -> 2.7558608e+09 | F10: =IF(E10="","",$B10*(1+E10/100)) | G10: 9
A11: 2034 | B11: =IF(F10<>"",F10,D10) -> 2.7558608e+09 | C11: 4 | D11: =$B11*(1+C11/100) -> 2.8660952e+09 | F11: =IF(E11="","",$B11*(1+E11/100)) | G11: 10
A12: 2035 | B12: =IF(F11<>"",F11,D11) -> 2.8660952e+09 | C12: 4 | D12: =$B12*(1+C12/100) -> 2.980739e+09 | F12: =IF(E12="","",$B12*(1+E12/100)) | G12: 11

Sheet Giá nhà hiện tại

Sheet Master Data
A2: MD-0 | D2: =IF(D3<>"", "MD-" & COUNTIF($D3:D3, "<>"), "") -> MD-1 | E2: =IF(E3<>"", "MD-" & COUNTIF($D3:E3, "<>"), "") | F2: =IF(F3<>"", "MD-" & COUNTIF($D3:F3, "<>"), "") | G2: =IF(G3<>"", "MD-" & COUNTIF($D3:G3, "<>"), "") | H2: =IF(H3<>"", "MD-" & COUNTIF($D3:H3, "<>"), "") -> MD-2 | J2: =IF(J3<>"", "MD-" & COUNTIF($D3:J3, "<>"), "") | K2: =IF(K3<>"", "MD-" & COUNTIF($D3:K3, "<>"), "") -> MD-3 | L2: =IF(L3<>"", "MD-" & COUNTIF($D3:L3, "<>"), "") | M2: =IF(M3<>"", "MD-" & COUNTIF($D3:M3, "<>"), "") | N2: =IF(N3<>"", "MD-" & COUNTIF($D3:N3, "<>"), "") | O2: =IF(O3<>"", "MD-" & COUNTIF($D3:O3, "<>"), "") | P2: =IF(P3<>"", "MD-" & COUNTIF($D3:P3, "<>"), "") -> MD-4 | Q2: =IF(Q3<>"", "MD-" & COUNTIF($D3:Q3, "<>"), "") | ... AX2: =IF(AX3<>"", "MD-" & COUNTIF($D3:AX3, "<>"), "") -> MD-9 | AZ2: =IF(AZ3<>"", "MD-" & COUNTIF($D3:AZ3, "<>"), "") | BA2: =IF(BA3<>"", "MD-" & COUNTIF($D3:BA3, "<>"), "") | BB2: =IF(BB3<>"", "MD-" & COUNTIF($D3:BB3, "<>"), "") | BC2: =IF(BC3<>"", "MD-" & COUNTIF($D3:BC3, "<>"), "") | BD2: =IF(BD3<>"", "MD-" & COUNTIF($D3:BD3, "<>"), "") | BF2: =IF(BF3<>"", "MD-" & COUNTIF($D3:BF3, "<>"), "") | BG2: =IF(BG3<>"", "MD-" & COUNTIF($D3:BG3, "<>"), "") | BH2: =IF(BH3<>"", "MD-" & COUNTIF($D3:BH3, "<>"), "") -> MD-10 | BI2: =IF(BI3<>"", "MD-" & COUNTIF($D3:BI3, "<>"), "") | BJ2: =IF(BJ3<>"", "MD-" & COUNTIF($D3:BJ3, "<>"), "") | BK2: =IF(BK3<>"", "MD-" & COUNTIF($D3:BK3, "<>"), "") | BL2: =IF(BL3<>"", "MD-" & COUNTIF($D3:BL3, "<>"), "") | BM2: =IF(BM3<>"", "MD-" & COUNTIF($D3:BM3, "<>"), "") | ... ER2: =IF(ER3<>"", "MD-" & COUNTIF($D3:ER3, "<>"), "")
A3: Danh sách Master Data | D3: Tổ chức | H3: Loại dữ liệu chủ | K3: Tiêu chí chọn trọ, chọn nhà | P3: Chủ đề | V3: Ngôi nhà mơ ước | AF3: Phòng | AK3: Mục tiêu và hành động cụ thể | AQ3: Hành động cụ thể | AX3: Danh sách các khu vực muốn sống | BH3: Tỉnh Thành
A4: STT | B4: Tên | D4: Tên tiếng Anh | E4: Tên tiếng Việt | F4: Mô tả | H4: Loại | I4: Giá trị | K4: STT | L4: Tiêu chí chính | M4: Tiêu chí cụ thể | N4: Mô tả / Gợi ý đánh giá | P4: STT | Q4: Tiêu đề tiếng Việt | R4: Tiêu đề tiếng Anh | S4: Tổ chức | T4: Link | V4: STT | W4: Phòng | X4: Nhu cầu | Y4: Mô tả | Z4: Dài | AA4: Rộng | AB4: Khoảng trống | AC4: Diện tích tối thiểu (m²) | AD4: Diện tích lý tưởng (m²) | AF4: STT | AG4: Tên phòng | AH4: Diện tích tối thiểu | AI4: Diện tích lý tưởng | AK4: STT | AL4: Mục tiêu | AM4: Chi tiết / Cụ thể | AN4: Thời gian dự kiến | AO4: Hành động cụ thể | AQ4: STT | AR4: Mục tiêu liên quan | AS4: Hành động cụ thể | AT4: Thời hạn | AU4: Trạng thái | AV4: Ghi chú / Tiến độ | AX4: ID | AY4: TinhThanh | AZ4: KhuVuc | BA4: Quan | BB4: LoaiThongTin | BC4: MaMaster | BD4: NoiDung | BF4: GhiChu | BH4: Tỉnh Thành | BJ4: ID | BK4: LoaiThongTin | BL4: NhomChuDe | BM4: NoiDungChiTiet | BN4: DoiTuongPhuHop | BO4: GhiChu
A5: {=TRANSPOSE(_xlfn.UNIQUE(_xlfn._xlws.FILTER($B2:$AAC2, $B2:$AAC2<>"")))} -> MD-1 | B5: {=TRANSPOSE(_xlfn.UNIQUE(_xlfn._xlws.FILTER($D3:$AAC3, $D3:$AAC3<>"")))} -> Tổ chức | D5: World Bank | E5: Ngân hàng Thế giới | F5: Tổ chức tài chính quốc tế cung cấp các khoản vay và hỗ trợ phát triển cho các nước đang phát triển hằm mục tiêu giảm nghèo và thúc đẩy thịnh vượng chung | H5: Trạng thái | I5: To Do | K5: =IF(L4<>"", IF(ISNUMBER(K4), K4+1, 1), "") -> 1 | L5: Vị trí | M5: Thuận tiện di chuyển | N5: Nên chọn phòng gần trường học hoặc nơi làm việc để tiết kiệm thời gian và chi phí đi lại. | P5: =IF(Q4<>"", IF(ISNUMBER(P4), P4+1, 1), "") -> 1 | Q5: Dữ liệu lạm phát Việt Nam 2000–2025 | R5: Inflation, consumer prices (annual %) - Viet Nam | S5: World Bank | T5: https://data.worldbank.org/indicator/FP.CPI.TOTL.ZG?locations=VN | V5: =IF(W4<>"", IF(ISNUMBER(V4), V4+1, 1), "") -> 1 | W5: Phòng ngủ chính | X5: Giường King size | Y5: Giường 1.8×2.0m | AC5: 3.6 | AD5: 4 | AF5: =IF(AG4<>"", IF(ISNUMBER(AF4), AF4+1, 1), "") -> 1 | AG5: Phòng ngủ chính | AH5: =SUMIF(W5:AC21,AG5,AC5:AC21) -> 11.3 | AI5: =SUMIF(W5:AD21,AG5,AD5:AD21) -> 14 | AK5: =IF(AL4<>"", IF(ISNUMBER(AK4), AK4+1, 1), "") -> 1 | AL5: Có nhà và tự do tài chính | AM5: Mua căn nhà [số phòng, vị trí cụ thể], đạt tự do tài chính với chi phí sinh hoạt hàng tháng X VNĐ | AN5: 10 năm | AO5: Xác định giá nhà, tính chi phí tự do tài chính, lập kế hoạch tổng thể | AQ5: =IF(AR4<>"", IF(ISNUMBER(AQ4), AQ4+1, 1), "") -> 1 | AR5: Biết được số tiền cần có | AS5: Liệt kê danh sách các khu vực muốn sống | AT5: 2 tuần | AU5: To Do | AV5: Liệt kê giá nhà theo khu vực, diện tích, mỗi khu vực phân tích toàn bộ chủ đề/tiêu chí để so sánh | AX5: 1 | AY5: Hồ Chí Minh | AZ5: TP. Thủ Đức | BA5: Quận 2 | BB5: Ưu điểm | BC5: U02 | BD5: Khu vực quy hoạch mới, hiện đại | BE5: =IFERROR(VLOOKUP(BC5,'Master Data'!$BJ$5:$BM$100,4,FALSE),"") -> Khu vực quy hoạch mới, hiện đại | BF5: Quy hoạch bài bản, gần Thủ Thiêm | BG5: =BD5=BE5 -> TRUE | BJ5: U01 | BK5: Ưu điểm | BL5: Giao thông | BM5: Gần trung tâm, di chuyển thuận tiện | BN5: Dân văn phòng, doanh nhân | BO5: Phù hợp người làm việc ở trung tâm
A6: MD-2 | B6: Loại dữ liệu chủ | D6: Federal Reserve Bank of Cleveland | E6: Ngân hàng Dự trữ Liên bang Cleveland | F6: một trong 12 ngân hàng khu vực của Cục Dự trữ Liên bang Hoa Kỳ (Fed) | H6: Trạng thái | I6: In progress | K6: =IF(L5<>"", IF(ISNUMBER(K5), K5+1, 1), "") -> 2 | L6: Vị trí | M6: Giao thông | N6: Ưu tiên khu vực ít kẹt xe, có tuyến xe buýt công cộng, đường dễ đi và an toàn. | P6: =IF(Q5<>"", IF(ISNUMBER(P5), P5+1, 1), "") -> 2 | Q6: Lạm phát trung bình hằng năm trong 10 năm tới | R6: 10-year expected inflation | S6: Federal Reserve Bank of Cleveland | T6: https://www.clevelandfed.org/indicators-and-data/inflation-expectations?utm_source=chatgpt.com | V6: =IF(W5<>"", IF(ISNUMBER(V5), V5+1, 1), "") -> 2 | W6: Phòng ngủ chính | X6: Tivi 55" | Y6: Tivi cách giường 2.1–2.3m | AC6: 1 | AD6: 1.5 | AF6: =IF(AG5<>"", IF(ISNUMBER(AF5), AF5+1, 1), "") -> 2 | AG6: Phòng ngủ phụ | AH6: =SUMIF(W6:AC22,AG6,AC6:AC22) -> 4 | AI6: =SUMIF(W6:AD22,AG6,AD6:AD22) -> 4.5 | AK6: =IF(AL5<>"", IF(ISNUMBER(AK5), AK5+1, 1), "") -> 2 | AL6: Biết được số tiền cần có | AM6: Tính tổng chi phí mua nhà + quỹ đầu tư đủ chi phí sinh hoạt khi tự do tài chính | AN6: 1-2 tháng | AO6: Nghiên cứu giá nhà, chi phí sinh hoạt, tính quỹ cần có | AQ6: =IF(AR5<>"", IF(ISNUMBER(AQ5), AQ5+1, 1), "") -> 2 | AR6: Biết được số tiền cần có | AS6: Nghiên cứu giá nhà mục tiêu cho từng khu vực muốn sống | AT6: 2 tuần | AU6: To Do | AV6: Liệt kê giá nhà theo khu vực, diện tích | AX6: 2 | AY6: Hồ Chí Minh | AZ6: TP. Thủ Đức | BA6: Quận 2 | BB6: Ưu điểm | BC6: U04 | BD6: Tiềm năng tăng giá, nhiều dự án mới | BE6: =IFERROR(VLOOKUP(BC6,'Master Data'!$BJ$5:$BM$100,4,FALSE),"") -> Tiềm năng tăng giá, nhiều dự án mới | BF6: Có nhiều dự án cao cấp, chủ đầu tư lớn | BG6: =BD6=BE6 -> TRUE | BJ6: U01-1 | BK6: Ưu điểm | BL6: Giao thông | BM6: Nhiều tuyến đường lớn, kết nối các quận trọng điểm | BN6: Người di chuyển thường xuyên | BO6: Ví dụ: Q1, Q3, Phú Nhuận
A7: MD-3 | B7: Tiêu chí chọn trọ, chọn nhà | D7: Trading Economics | F7: Nền tảng cung cấp dữ liệu kinh tế, chỉ số tài chính và phân tích thị trường cho hơn 200 quốc gia, bao gồm dữ liệu lịch sử, dự báo và thông tin cập nhật | H7: Trạng thái | I7: Done | K7: =IF(L6<>"", IF(ISNUMBER(K6), K6+1, 1), "") -> 3 | L7: Vị trí | M7: Tiện ích xung quanh | N7: Gần chợ, siêu thị, cửa hàng tiện lợi, bệnh viện, trạm ATM giúp sinh hoạt hàng ngày thuận tiện. | P7: =IF(Q6<>"", IF(ISNUMBER(P6), P6+1, 1), "") -> 3 | Q7: Tỷ lệ lạm phát của Việt Nam | R7: Vietnam Inflation Rate | S7: Trading Economics | T7: https://tradingeconomics.com/vietnam/inflation-cpi | V7: =IF(W6<>"", IF(ISNUMBER(V6), V6+1, 1), "") -> 3 | W7: Phòng ngủ chính | X7: 2 bàn làm việc | Y7: Bàn 1.2×0.6m | AC7: 1.5 | AD7: 2 | AF7: =IF(AG6<>"", IF(ISNUMBER(AF6), AF6+1, 1), "") -> 3 | AG7: Phòng khách | AH7: =SUMIF(W7:AC23,AG7,AC7:AC23) -> 13.5 | AI7: =SUMIF(W7:AD23,AG7,AD7:AD23) -> 17 | AK7: =IF(AL6<>"", IF(ISNUMBER(AK6), AK6+1, 1), "") -> 3 | AL7: Biết được số tiền cần đầu tư & thời gian | AM7: Tính toán số tiền đầu tư hàng tháng và thời gian cần để đạt mục tiêu | AN7: 1-2 tháng | AO7: Lập bảng dự báo đầu tư theo lãi suất kỳ vọng, phân chia giai đoạn: mua nhà, quỹ tự do tài chính | AQ7: =IF(AR6<>"", IF(ISNUMBER(AQ6), AQ6+1, 1), "") -> 3 | AR7: Biết được số tiền cần có | AS7: Tính chi phí sinh hoạt hàng tháng khi tự do tài chính | AT7: 2 tuần | AU7: To Do | AV7: Bao gồm ăn uống, đi lại, giải trí, y tế,… | AX7: 3 | AY7: Hồ Chí Minh | AZ7: TP. Thủ Đức | BA7: Quận 2 | BB7: Ưu điểm | BD7: Có trường quốc tế, bệnh viện quốc tế | BE7: =IFERROR(VLOOKUP(BC7,'Master Data'!$BJ$5:$BM$100,4,FALSE),"") | BF7: Phù hợp chuyên gia, người nước ngoài | BG7: =BD7=BE7 -> FALSE | BJ7: U01-2 | BK7: Ưu điểm | BL7: Giao thông | BM7: Có metro, cao tốc, hoặc cầu mới giúp rút ngắn thời gian di chuyển | BN7: Người đi làm xa | BO7: Thích hợp Thủ Đức, Quận 9
A8: MD-4 | B8: Chủ đề | H8: Loại thông tin | I8: Ưu điểm | K8: =IF(L7<>"", IF(ISNUMBER(K7), K7+1, 1), "") -> 4 | L8: Ngân sách | M8: Xác định chi phí | N8: Lập kế hoạch bao gồm: tiền thuê, điện, nước, internet, gửi xe, chi phí phát sinh. | P8: =IF(Q7<>"", IF(ISNUMBER(P7), P7+1, 1), "") -> 4 | V8: =IF(W7<>"", IF(ISNUMBER(V7), V7+1, 1), "") -> 4 | W8: Phòng ngủ chính | X8: Tủ quần áo | Y8: Tủ 2×0.6m | AC8: 1.2 | AD8: 1.5 | AF8: =IF(AG7<>"", IF(ISNUMBER(AF7), AF7+1, 1), "") -> 4 | AG8: Phòng bếp | AH8: =SUMIF(W8:AC24,AG8,AC8:AC24) -> 9.5 | AI8: =SUMIF(W8:AD24,AG8,AD8:AD24) -> 11.5 | AK8: =IF(AL7<>"", IF(ISNUMBER(AK7), AK7+1, 1), "") -> 4 | AL8: Biết thu nhập cần thiết | AM8: Xác định số tiền kiếm mỗi tháng để đủ đầu tư | AN8: 1 tháng | AO8: Tính toán dựa trên tỷ lệ tiết kiệm / đầu tư, bổ sung nguồn thu nhập thêm nếu cần | AQ8: =IF(AR7<>"", IF(ISNUMBER(AQ7), AQ7+1, 1), "") -> 4 | AR8: Biết được số tiền cần có | AS8: Tính chi phí sinh hoạt hàng tháng khi tự do tài chính | AT8: 2 tuần | AU8: To Do | AV8: Bao gồm ăn uống, đi lại, giải trí, y tế,… | AX8: 4 | AY8: Hồ Chí Minh | AZ8: TP. Thủ Đức | BA8: Quận 2 | BB8: Nhược điểm | BC8: N07-1 | BD8: Kết nối phụ thuộc cầu/đường độc đạo | BE8: =IFERROR(VLOOKUP(BC8,'Master Data'!$BJ$5:$BM$100,4,FALSE),"") -> Kết nối phụ thuộc cầu/đường độc đạo | BF8: Kẹt cầu Thủ Thiêm, cầu Sài Gòn giờ cao điểm | BG8: =BD8=BE8 -> TRUE | BJ8: U02 | BK8: Ưu điểm | BL8: Quy hoạch | BM8: Khu vực quy hoạch mới, hiện đại | BN8: Nhà đầu tư, chuyên gia | BO8: Ví dụ: Q2, Q7, TP Thủ Đức
A9: MD-5 | B9: Ngôi nhà mơ ước | H9: Loại thông tin | I9: Nhược điểm | K9: =IF(L8<>"", IF(ISNUMBER(K8), K8+1, 1), "") -> 5 | L9: Ngân sách | M9: Phù hợp với khả năng tài chính | N9: Tiền thuê nên chiếm tối đa 30–40% thu nhập hàng tháng để đảm bảo cân đối chi tiêu. | P9: =IF(Q8<>"", IF(ISNUMBER(P8), P8+1, 1), "") | V9: =IF(W8<>"", IF(ISNUMBER(V8), V8+1, 1), "") -> 5 | W9: Phòng ngủ chính | X9: Phòng tắm khép kín | Y9: Bồn tắm 1.8×0.8m; lối đi tối thiểu 0.8m | AC9: 4 | AD9: 5 | AF9: =IF(AG8<>"", IF(ISNUMBER(AF8), AF8+1, 1), "") -> 5 | AG9: Ban công | AH9: =SUMIF(W9:AC25,AG9,AC9:AC25) -> 5 | AI9: =SUMIF(W9:AD25,AG9,AD9:AD25) -> 6.5 | AK9: =IF(AL8<>"", IF(ISNUMBER(AK8), AK8+1, 1), "") -> 5 | AL9: Lập kế hoạch hành động hàng tháng | AM9: Học kỹ năng cần thiết, tăng thu nhập, tiết kiệm và đầu tư | AN9: Hàng tháng / Hàng quý | AO9: Liệt kê kỹ năng cần học, khóa học, kế hoạch tăng lương (%), theo dõi tiết kiệm và đầu tư hàng tháng | AQ9: =IF(AR8<>"", IF(ISNUMBER(AQ8), AQ8+1, 1), "") -> 5 | AR9: Biết được số tiền cần đầu tư & thời gian | AS9: Lập bảng dự báo đầu tư hàng tháng | AT9: 1 tháng | AU9: To Do | AV9: Xác định lãi suất kỳ vọng, loại hình đầu tư | AX9: 5 | AY9: Hồ Chí Minh | AZ9: TP. Thủ Đức | BA9: Quận 9 | BB9: Ưu điểm | BC9: U03 | BD9: Nhiều cây xanh, không gian thoáng | BE9: =IFERROR(VLOOKUP(BC9,'Master Data'!$BJ$5:$BM$100,4,FALSE),"") -> Nhiều cây xanh, không gian thoáng | BF9: Gần khu công nghệ cao, sông Đồng Nai | BG9: =BD9=BE9 -> TRUE | BJ9: U02-1 | BK9: Ưu điểm | BL9: Quy hoạch | BM9: Có quy hoạch đồng bộ hạ tầng – tiện ích – cây xanh | BN9: Nhà đầu tư dài hạn | BO9: Tiềm năng tăng giá tốt
A10: MD-6 | B10: Phòng | K10: =IF(L9<>"", IF(ISNUMBER(K9), K9+1, 1), "") -> 6 | L10: Cơ sở vật chất & tiện nghi | M10: Tình trạng phòng | N10: Kiểm tra tường, trần, sàn, cửa, hệ thống điện nước. Tránh phòng ẩm mốc hoặc xuống cấp. | P10: =IF(Q9<>"", IF(ISNUMBER(P9), P9+1, 1), "") | V10: =IF(W9<>"", IF(ISNUMBER(V9), V9+1, 1), "") -> 6 | W10: Phòng ngủ phụ | X10: Giường Queen size | Y10: Giường 1.6×2.0m | AC10: 3.2 | AD10: 3.5 | AF10: =IF(AG9<>"", IF(ISNUMBER(AF9), AF9+1, 1), "") -> 6 | AG10: Nhà vệ sinh chung bên ngoài | AH10: =SUMIF(W10:AC26,AG10,AC10:AC26) -> 3 | AI10: =SUMIF(W10:AD26,AG10,AD10:AD26) -> 3.7 | AK10: =IF(AL9<>"", IF(ISNUMBER(AK9), AK9+1, 1), "") -> 6 | AQ10: =IF(AR9<>"", IF(ISNUMBER(AQ9), AQ9+1, 1), "") -> 6 | AR10: Biết thu nhập cần thiết | AS10: Tính thu nhập cần thiết để đầu tư đủ mỗi tháng | AT10: 1 tuần | AU10: To Do | AV10: Tính dựa trên tỷ lệ tiết kiệm, dự trù tăng thu nhập khác | AX10: 6 | AY10: Hồ Chí Minh | AZ10: TP. Thủ Đức | BA10: Quận 9 | BB10: Ưu điểm | BC10: U08 | BD10: Gần khu công nghệ cao, đại học | BE10: =IFERROR(VLOOKUP(BC10,'Master Data'!$BJ$5:$BM$100,4,FALSE),"") -> Gần khu công nghệ cao, đại học | BF10: Gần ĐHQG, nhiều khu R&D | BG10: =BD10=BE10 -> TRUE | BJ10: U02-2 | BK10: Ưu điểm | BL10: Quy hoạch | BM10: Định hướng phát triển đô thị thông minh | BN10: Chuyên gia, kỹ sư | BO10: Ví dụ: TP Thủ Đức
A11: MD-7 | B11: Mục tiêu và hành động cụ thể | K11: =IF(L10<>"", IF(ISNUMBER(K10), K10+1, 1), "") -> 7 | L11: Cơ sở vật chất & tiện nghi | M11: An ninh | N11: Ưu tiên phòng có khóa chắc, camera an ninh, cửa sắt, hoặc khu vực có bảo vệ. | P11: =IF(Q10<>"", IF(ISNUMBER(P10), P10+1, 1), "") | V11: =IF(W10<>"", IF(ISNUMBER(V10), V10+1, 1), "") -> 7 | W11: Phòng ngủ phụ | X11: Tivi 40" | Y11: Tivi cách giường 1.6–2.0m | AC11: 0.8 | AD11: 1 | AF11: =IF(AG10<>"", IF(ISNUMBER(AF10), AF10+1, 1), "") -> 7 | AK11: =IF(AL10<>"", IF(ISNUMBER(AK10), AK10+1, 1), "") | AQ11: =IF(AR10<>"", IF(ISNUMBER(AQ10), AQ10+1, 1), "") -> 7 | AR11: Lập kế hoạch hành động hàng tháng | AS11: Liệt kê các kỹ năng cần học và khóa học tham gia | AT11: Hàng tháng | AU11: To Do | AV11: Ví dụ: đầu tư, quản lý tài chính, kỹ năng tăng thu nhập | AX11: 7 | AY11: Hồ Chí Minh | AZ11: TP. Thủ Đức | BA11: Quận 9 | BB11: Ưu điểm | BC11: U07 | BD11: Giá còn mềm so với trung tâm | BE11: =IFERROR(VLOOKUP(BC11,'Master Data'!$BJ$5:$BM$100,4,FALSE),"") -> Giá còn mềm so với trung tâm | BF11: Quỹ đất lớn, tiềm năng tăng | BG11: =BD11=BE11 -> TRUE | BJ11: U03 | BK11: Ưu điểm | BL11: Môi trường sống | BM11: Nhiều cây xanh, không gian thoáng | BN11: Gia đình trẻ, người cao tuổi | BO11: Thoáng mát, ít ô nhiễm
A12: MD-8 | B12: Hành động cụ thể | K12: =IF(L11<>"", IF(ISNUMBER(K11), K11+1, 1), "") -> 8 | L12: Cơ sở vật chất & tiện nghi | M12: Thoáng mát & ánh sáng | N12: Có cửa sổ, gió và ánh sáng tự nhiên; không bị hầm, bí, hoặc hướng nắng gắt. | P12: =IF(Q11<>"", IF(ISNUMBER(P11), P11+1, 1), "") | V12: =IF(W11<>"", IF(ISNUMBER(V11), V11+1, 1), "") -> 8 | W12: Phòng khách | X12: Bộ sofa 10 người | Y12: Sofa chữ L/U 4×3m | AC12: 12 | AD12: 15 | AF12: =IF(AG11<>"", IF(ISNUMBER(AF11), AF11+1, 1), "") | AK12: =IF(AL11<>"", IF(ISNUMBER(AK11), AK11+1, 1), "") | AQ12: =IF(AR11<>"", IF(ISNUMBER(AQ11), AQ11+1, 1), "") -> 8 | AR12: Lập kế hoạch hành động hàng tháng | AS12: Lập kế hoạch tăng lương / thu nhập thêm | AT12: Hàng tháng | AU12: To Do | AV12: Ví dụ: tăng lương 5%/tháng, freelance, kinh doanh phụ | AX12: 8 | AY12: Hồ Chí Minh | AZ12: TP. Thủ Đức | BA12: Quận 9 | BB12: Nhược điểm | BC12: N01 | BD12: Kẹt xe, di chuyển khó, xa trung tâm | BE12: =IFERROR(VLOOKUP(BC12,'Master Data'!$BJ$5:$BM$100,4,FALSE),"") -> Kẹt xe, di chuyển khó, xa trung tâm | BF12: Xa Q1, hay kẹt cao tốc Long Thành | BG12: =BD12=BE12 -> TRUE | BJ12: U03-1 | BK12: Ưu điểm | BL12: Môi trường sống | BM12: Có sông, hồ, công viên gần nhà | BN12: Gia đình có trẻ nhỏ | BO12: Không khí trong lành
A13: MD-9 | B13: Danh sách các khu vực muốn sống | K13: =IF(L12<>"", IF(ISNUMBER(K12), K12+1, 1), "") -> 9 | L13: Cơ sở vật chất & tiện nghi | M13: Thiết bị đi kèm | N13: Ghi rõ có sẵn giường, tủ, quạt, máy lạnh, bàn học… để so sánh giá thuê hợp lý. | P13: =IF(Q12<>"", IF(ISNUMBER(P12), P12+1, 1), "") | V13: =IF(W12<>"", IF(ISNUMBER(V12), V12+1, 1), "") -> 9 | W13: Phòng khách | X13: Tivi 60" | Y13: Tivi cách sofa 2.4–3.0m | AC13: 1.5 | AD13: 2 | AF13: =IF(AG12<>"", IF(ISNUMBER(AF12), AF12+1, 1), "") | AK13: =IF(AL12<>"", IF(ISNUMBER(AK12), AK12+1, 1), "") | AQ13: =IF(AR12<>"", IF(ISNUMBER(AQ12), AQ12+1, 1), "") -> 9 | AR13: Lập kế hoạch hành động hàng tháng | AS13: Lập kế hoạch tiết kiệm & đầu tư hàng tháng | AT13: Hàng tháng | AU13: To Do | AV13: Xác định số tiền tiết kiệm, số tiền đầu tư, theo dõi % đạt được | AX13: 9 | AY13: Hồ Chí Minh | AZ13: TP. Thủ Đức | BA13: Quận 9 | BB13: Nhược điểm | BC13: N02 | BD13: Hạ tầng cũ, đường nhỏ, dễ ngập | BE13: =IFERROR(VLOOKUP(BC13,'Master Data'!$BJ$5:$BM$100,4,FALSE),"") -> Hạ tầng cũ, đường nhỏ, dễ ngập | BF13: Một số khu chưa nâng cấp | BG13: =BD13=BE13 -> TRUE | BJ13: U04 | BK13: Ưu điểm | BL13: Giá trị BĐS | BM13: Tiềm năng tăng giá, nhiều dự án mới | BN13: Nhà đầu tư, người mua tích sản | BO13: Vùng đang phát triển mạnh
A14: MD-10 | B14: Tỉnh Thành | K14: =IF(L13<>"", IF(ISNUMBER(K13), K13+1, 1), "") -> 10 | L14: Môi trường sống | M14: Yên tĩnh | N14: Nên chọn khu dân cư ít tiếng ồn, tránh gần đường lớn, quán nhậu, karaoke. | P14: =IF(Q13<>"", IF(ISNUMBER(P13), P13+1, 1), "") | V14: =IF(W13<>"", IF(ISNUMBER(V13), V13+1, 1), "") -> 10 | W14: Phòng bếp | X14: Bếp nấu | Y14: Khu bếp dài 4m | AC14: 6 | AD14: 7 | AF14: =IF(AG13<>"", IF(ISNUMBER(AF13), AF13+1, 1), "") | AK14: =IF(AL13<>"", IF(ISNUMBER(AK13), AK13+1, 1), "") | AQ14: =IF(AR13<>"", IF(ISNUMBER(AQ13), AQ13+1, 1), "") -> 10 | AR14: Tracking tổng thể | AS14: Kiểm tra tiến độ mỗi tuần | AT14: Hàng tuần | AU14: To Do | AV14: Note % hoàn thành, điều chỉnh kế hoạch nếu cần | AX14: 10 | AY14: Hồ Chí Minh | AZ14: TP. Thủ Đức | BA14: Quận Thủ Đức | BB14: Ưu điểm | BC14: U08 | BD14: Gần khu công nghệ cao, đại học | BE14: =IFERROR(VLOOKUP(BC14,'Master Data'!$BJ$5:$BM$100,4,FALSE),"") -> Gần khu công nghệ cao, đại học | BF14: Gần ĐHQG, metro tuyến 1 | BG14: =BD14=BE14 -> TRUE | BJ14: U04-1 | BK14: Ưu điểm | BL14: Giá trị BĐS | BM14: Được nhiều chủ đầu tư lớn tập trung | BN14: Nhà đầu tư | BO14: Ví dụ: Novaland, Vingroup
K15: =IF(L14<>"", IF(ISNUMBER(K14), K14+1, 1), "") -> 11 | L15: Môi trường sống | M15: Sạch sẽ & vệ sinh chung | N15: Kiểm tra khu vực rác, nhà vệ sinh chung, hành lang, môi trường xung quanh. | P15: =IF(Q14<>"", IF(ISNUMBER(P14), P14+1, 1), "") | V15: =IF(W14<>"", IF(ISNUMBER(V14), V14+1, 1), "") -> 11 | W15: Phòng bếp | X15: Bàn ăn 4 người | Y15: Bàn ăn 2×1.5m; lối đi xung quanh 0.9m | AC15: 3.5 | AD15: 4.5 | AF15: =IF(AG14<>"", IF(ISNUMBER(AF14), AF14+1, 1), "") | AK15: =IF(AL14<>"", IF(ISNUMBER(AK14), AK14+1, 1), "") | AQ15: =IF(AR14<>"", IF(ISNUMBER(AQ14), AQ14+1, 1), "") -> 11 | AX15: 11 | AY15: Hồ Chí Minh | AZ15: TP. Thủ Đức | BA15: Quận Thủ Đức | BB15: Ưu điểm | BC15: U05 | BD15: Đầy đủ tiện ích: trường, bệnh viện, TTTM | BE15: =IFERROR(VLOOKUP(BC15,'Master Data'!$BJ$5:$BM$100,4,FALSE),"") -> Đầy đủ tiện ích: trường, bệnh viện, TTTM | BF15: Có Vincom, bệnh viện, trường cấp 1–3 | BG15: =BD15=BE15 -> TRUE | BJ15: U05 | BK15: Ưu điểm | BL15: Tiện ích | BM15: Đầy đủ tiện ích: trường, bệnh viện, TTTM | BN15: Gia đình có con nhỏ | BO15: Sinh hoạt thuận tiện
K16: =IF(L15<>"", IF(ISNUMBER(K15), K15+1, 1), "") -> 12 | L16: Hợp đồng & quy định | M16: Đọc kỹ hợp đồng | N16: Xem rõ điều khoản: tiền thuê, cọc, thời hạn, quy định thanh toán, bồi thường. | P16: =IF(Q15<>"", IF(ISNUMBER(P15), P15+1, 1), "") | V16: =IF(W15<>"", IF(ISNUMBER(V15), V15+1, 1), "") -> 12 | W16: Ban công | X16: Trồng cây | Y16: Diện tích ≥2×1.5m | AC16: 3 | AD16: 3.5 | AF16: =IF(AG15<>"", IF(ISNUMBER(AF15), AF15+1, 1), "") | AK16: =IF(AL15<>"", IF(ISNUMBER(AK15), AK15+1, 1), "") | AQ16: =IF(AR15<>"", IF(ISNUMBER(AQ15), AQ15+1, 1), "") | AX16: 12 | AY16: Hồ Chí Minh | AZ16: TP. Thủ Đức | BA16: Quận Thủ Đức | BB16: Nhược điểm | BC16: N02 | BD16: Hạ tầng cũ, đường nhỏ, dễ ngập | BE16: =IFERROR(VLOOKUP(BC16,'Master Data'!$BJ$5:$BM$100,4,FALSE),"") -> Hạ tầng cũ, đường nhỏ, dễ ngập | BF16: Đường Kha Vạn Cân, Linh Đông dễ ngập | BG16: =BD16=BE16 -> TRUE | BJ16: U05-1 | BK16: Ưu điểm | BL16: Tiện ích | BM16: Có trung tâm mua sắm, siêu thị lớn gần nhà | BN16: Gia đình, người trẻ | BO16: AEON, Crescent Mall, Vincom
K17: =IF(L16<>"", IF(ISNUMBER(K16), K16+1, 1), "") -> 13 | L17: Hợp đồng & quy định | M17: Thỏa thuận rõ ràng với chủ nhà | N17: Trao đổi trước về giờ giấc, khách đến chơi, vật nuôi, sửa chữa thiết bị… | P17: =IF(Q16<>"", IF(ISNUMBER(P16), P16+1, 1), "") | V17: =IF(W16<>"", IF(ISNUMBER(V16), V16+1, 1), "") -> 13 | W17: Ban công | X17: Máy giặt | Y17: Khu vực để máy giặt | AC17: 1 | AD17: 1.5 | AF17: =IF(AG16<>"", IF(ISNUMBER(AF16), AF16+1, 1), "") | AK17: =IF(AL16<>"", IF(ISNUMBER(AK16), AK16+1, 1), "") | AQ17: =IF(AR16<>"", IF(ISNUMBER(AQ16), AQ16+1, 1), "") | AX17: 13 | AY17: Hồ Chí Minh | AZ17: Trung tâm | BA17: Quận 1 | BB17: Ưu điểm | BC17: U01 | BD17: Gần trung tâm, di chuyển thuận tiện | BE17: =IFERROR(VLOOKUP(BC17,'Master Data'!$BJ$5:$BM$100,4,FALSE),"") -> Gần trung tâm, di chuyển thuận tiện | BF17: Trung tâm hành chính, thương mại | BG17: =BD17=BE17 -> TRUE | BJ17: U06 | BK17: Ưu điểm | BL17: An ninh | BM17: Khu vực an ninh, dân trí cao | BN17: Người nước ngoài, chuyên gia | BO17: Quản lý nghiêm ngặt
K18: =IF(L17<>"", IF(ISNUMBER(K17), K17+1, 1), "") -> 14 | L18: Hợp đồng & quy định | M18: Thủ tục pháp lý | N18: Yêu cầu cung cấp giấy tờ sở hữu và làm thủ tục đăng ký tạm trú theo quy định. | P18: =IF(Q17<>"", IF(ISNUMBER(P17), P17+1, 1), "") | V18: =IF(W17<>"", IF(ISNUMBER(V17), V17+1, 1), "") -> 14 | W18: Ban công | X18: Phơi đồ | Y18: Khu vực phơi đồ | AC18: 1 | AD18: 1.5 | AF18: =IF(AG17<>"", IF(ISNUMBER(AF17), AF17+1, 1), "") | AK18: =IF(AL17<>"", IF(ISNUMBER(AK17), AK17+1, 1), "") | AQ18: =IF(AR17<>"", IF(ISNUMBER(AQ17), AQ17+1, 1), "") | AX18: 14 | AY18: Hồ Chí Minh | AZ18: Trung tâm | BA18: Quận 1 | BB18: Ưu điểm | BC18: U05 | BD18: Đầy đủ tiện ích cao cấp | BE18: =IFERROR(VLOOKUP(BC18,'Master Data'!$BJ$5:$BM$100,4,FALSE),"") -> Đầy đủ tiện ích: trường, bệnh viện, TTTM | BF18: Có trung tâm thương mại, bệnh viện lớn | BG18: =BD18=BE18 -> FALSE | BJ18: U06-1 | BK18: Ưu điểm | BL18: An ninh | BM18: Có bảo vệ 24/7, camera, cổng kiểm soát | BN18: Gia đình có trẻ nhỏ | BO18: Khu compound, căn hộ cao cấp
V19: =IF(W18<>"", IF(ISNUMBER(V18), V18+1, 1), "") -> 15 | W19: Nhà vệ sinh chung bên ngoài | X19: Bồn cầu | Y19: Tiện ích cơ bản | AC19: 1 | AD19: 1.2 | AF19: =IF(AG18<>"", IF(ISNUMBER(AF18), AF18+1, 1), "") | AK19: =IF(AL18<>"", IF(ISNUMBER(AK18), AK18+1, 1), "") | AQ19: =IF(AR18<>"", IF(ISNUMBER(AQ18), AQ18+1, 1), "") | AX19: 15 | AY19: Hồ Chí Minh | AZ19: Trung tâm | BA19: Quận 1 | BB19: Ưu điểm | BC19: U09 | BD19: Cộng đồng dân cư văn minh, ổn định | BE19: =IFERROR(VLOOKUP(BC19,'Master Data'!$BJ$5:$BM$100,4,FALSE),"") -> Cộng đồng dân cư văn minh, ổn định | BF19: Dân trí cao, nhiều người nước ngoài | BG19: =BD19=BE19 -> TRUE | BJ19: U07 | BK19: Ưu điểm | BL19: Giá cả | BM19: Giá còn mềm so với trung tâm | BN19: Người mua ở thật | BO19: Tiềm năng tăng giá dài hạn
V20: =IF(W19<>"", IF(ISNUMBER(V19), V19+1, 1), "") -> 16 | W20: Nhà vệ sinh chung bên ngoài | X20: Lavabo | Y20: Tiện ích cơ bản | AC20: 0.8 | AD20: 1 | AF20: =IF(AG19<>"", IF(ISNUMBER(AF19), AF19+1, 1), "") | AK20: =IF(AL19<>"", IF(ISNUMBER(AK19), AK19+1, 1), "") | AQ20: =IF(AR19<>"", IF(ISNUMBER(AQ19), AQ19+1, 1), "") | AX20: 16 | AY20: Hồ Chí Minh | AZ20: Trung tâm | BA20: Quận 1 | BB20: Nhược điểm | BC20: N03 | BD20: Giá cao, chi phí sinh hoạt đắt đỏ | BE20: =IFERROR(VLOOKUP(BC20,'Master Data'!$BJ$5:$BM$100,4,FALSE),"") -> Giá cao, chi phí sinh hoạt đắt đỏ | BF20: Giá BĐS và dịch vụ cao nhất TP | BG20: =BD20=BE20 -> TRUE | BJ20: U07-1 | BK20: Ưu điểm | BL20: Giá cả | BM20: Quỹ đất còn nhiều, dễ chọn vị trí | BN20: Nhà đầu tư, người trẻ | BO20: Ví dụ: Bình Chánh, Nhà Bè
V21: =IF(W20<>"", IF(ISNUMBER(V20), V20+1, 1), "") -> 17 | W21: Nhà vệ sinh chung bên ngoài | X21: Khu tắm đứng | Y21: Tiện ích cơ bản | AC21: 1.2 | AD21: 1.5 | AQ21: =IF(AR20<>"", IF(ISNUMBER(AQ20), AQ20+1, 1), "") | AX21: 17 | AY21: Hồ Chí Minh | AZ21: Trung tâm | BA21: Quận 3 | BB21: Ưu điểm | BC21: U01 | BD21: Gần trung tâm, di chuyển thuận tiện | BE21: =IFERROR(VLOOKUP(BC21,'Master Data'!$BJ$5:$BM$100,4,FALSE),"") -> Gần trung tâm, di chuyển thuận tiện | BF21: Gần Q1, khu văn minh | BG21: =BD21=BE21 -> TRUE | BJ21: U08 | BK21: Ưu điểm | BL21: Kết nối | BM21: Gần khu công nghệ cao, đại học | BN21: Kỹ sư, sinh viên | BO21: Nhiều cơ hội việc làm
V22: =IF(W21<>"", IF(ISNUMBER(V21), V21+1, 1), "") -> 18 | AQ22: =IF(AR21<>"", IF(ISNUMBER(AQ21), AQ21+1, 1), "") | AX22: 18 | AY22: Hồ Chí Minh | AZ22: Trung tâm | BA22: Quận 3 | BB22: Ưu điểm | BC22: U09 | BD22: Cộng đồng dân cư văn minh, ổn định | BE22: =IFERROR(VLOOKUP(BC22,'Master Data'!$BJ$5:$BM$100,4,FALSE),"") -> Cộng đồng dân cư văn minh, ổn định | BF22: Dân trí cao, có nhiều trường học | BG22: =BD22=BE22 -> TRUE | BJ22: U09 | BK22: Ưu điểm | BL22: Cộng đồng | BM22: Cộng đồng dân cư văn minh, ổn định | BN22: Gia đình trung lưu | BO22: Ít tệ nạn xã hội
V23: =IF(W22<>"", IF(ISNUMBER(V22), V22+1, 1), "") | AQ23: =IF(AR22<>"", IF(ISNUMBER(AQ22), AQ22+1, 1), "") | AX23: 19 | AY23: Hồ Chí Minh | AZ23: Trung tâm | BA23: Quận 3 | BB23: Nhược điểm | BC23: N02 | BD23: Hạ tầng cũ, đường nhỏ, dễ ngập | BE23: =IFERROR(VLOOKUP(BC23,'Master Data'!$BJ$5:$BM$100,4,FALSE),"") -> Hạ tầng cũ, đường nhỏ, dễ ngập | BF23: Đường nhỏ, khó đậu xe | BG23: =BD23=BE23 -> TRUE | BJ23: U10 | BK23: Ưu điểm | BL23: Dịch vụ cao cấp | BM23: Có trường quốc tế, bệnh viện quốc tế | BN23: Gia đình thu nhập cao | BO23: Phù hợp chuyên gia, người nước ngoài
V24: =IF(W23<>"", IF(ISNUMBER(V23), V23+1, 1), "") | AQ24: =IF(AR23<>"", IF(ISNUMBER(AQ23), AQ23+1, 1), "") | AX24: 20 | AY24: Hồ Chí Minh | AZ24: Vành trong | BA24: Quận 4 | BB24: Ưu điểm | BC24: U01 | BD24: Gần trung tâm, di chuyển thuận tiện | BE24: =IFERROR(VLOOKUP(BC24,'Master Data'!$BJ$5:$BM$100,4,FALSE),"") -> Gần trung tâm, di chuyển thuận tiện | BF24: Gần Q1, giá thấp hơn | BG24: =BD24=BE24 -> TRUE | BJ24: N01 | BK24: Nhược điểm | BL24: Giao thông | BM24: Kẹt xe, di chuyển khó, xa trung tâm | BN24: --- | BO24: Thường vào giờ cao điểm
V25: =IF(W24<>"", IF(ISNUMBER(V24), V24+1, 1), "") | AQ25: =IF(AR24<>"", IF(ISNUMBER(AQ24), AQ24+1, 1), "") | AX25: 21 | AY25: Hồ Chí Minh | AZ25: Vành trong | BA25: Quận 4 | BB25: Ưu điểm | BC25: U07 | BD25: Giá còn mềm so với trung tâm | BE25: =IFERROR(VLOOKUP(BC25,'Master Data'!$BJ$5:$BM$100,4,FALSE),"") -> Giá còn mềm so với trung tâm | BF25: Dễ tiếp cận BĐS trung tâm | BG25: =BD25=BE25 -> TRUE | BJ25: N01-1 | BK25: Nhược điểm | BL25: Giao thông | BM25: Hạ tầng giao thông chưa đồng bộ, dễ tắc đường | BN25: --- | BO25: Đặc biệt khu Q9, Bình Chánh
V26: =IF(W25<>"", IF(ISNUMBER(V25), V25+1, 1), "") | AQ26: =IF(AR25<>"", IF(ISNUMBER(AQ25), AQ25+1, 1), "") | AX26: 22 | AY26: Hồ Chí Minh | AZ26: Vành trong | BA26: Quận 4 | BB26: Nhược điểm | BC26: N02 | BD26: Hạ tầng cũ, đường nhỏ, dễ ngập | BE26: =IFERROR(VLOOKUP(BC26,'Master Data'!$BJ$5:$BM$100,4,FALSE),"") -> Hạ tầng cũ, đường nhỏ, dễ ngập | BF26: Hạ tầng hạn chế, ngập triều cường | BG26: =BD26=BE26 -> TRUE | BJ26: N02 | BK26: Nhược điểm | BL26: Hạ tầng | BM26: Hạ tầng cũ, đường nhỏ, dễ ngập | BN26: --- | BO26: Q4, Q5, Q8 hay gặp
V27: =IF(W26<>"", IF(ISNUMBER(V26), V26+1, 1), "") | AQ27: =IF(AR26<>"", IF(ISNUMBER(AQ26), AQ26+1, 1), "") | AX27: 23 | AY27: Hồ Chí Minh | AZ27: Vành trong | BA27: Quận 5 | BB27: Ưu điểm | BC27: U09 | BD27: Cộng đồng dân cư văn minh, ổn định | BE27: =IFERROR(VLOOKUP(BC27,'Master Data'!$BJ$5:$BM$100,4,FALSE),"") -> Cộng đồng dân cư văn minh, ổn định | BF27: Cộng đồng người Hoa, buôn bán sầm uất | BG27: =BD27=BE27 -> TRUE | BJ27: N02-1 | BK27: Nhược điểm | BL27: Hạ tầng | BM27: Thiếu vỉa hè, hệ thống thoát nước yếu | BN27: --- | BO27: Gây ngập khi mưa lớn
V28: =IF(W27<>"", IF(ISNUMBER(V27), V27+1, 1), "") | AQ28: =IF(AR27<>"", IF(ISNUMBER(AQ27), AQ27+1, 1), "") | AX28: 24 | AY28: Hồ Chí Minh | AZ28: Vành trong | BA28: Quận 5 | BB28: Ưu điểm | BC28: U05 | BD28: Tiện ích đầy đủ | BE28: =IFERROR(VLOOKUP(BC28,'Master Data'!$BJ$5:$BM$100,4,FALSE),"") -> Đầy đủ tiện ích: trường, bệnh viện, TTTM | BF28: Bệnh viện, trường học lớn, gần Q1 | BG28: =BD28=BE28 -> FALSE | BJ28: N03 | BK28: Nhược điểm | BL28: Giá cả | BM28: Giá cao, chi phí sinh hoạt đắt đỏ | BN28: --- | BO28: Q1, Q3, Phú Nhuận
V29: =IF(W28<>"", IF(ISNUMBER(V28), V28+1, 1), "") | AQ29: =IF(AR28<>"", IF(ISNUMBER(AQ28), AQ28+1, 1), "") | AX29: 25 | AY29: Hồ Chí Minh | AZ29: Vành trong | BA29: Quận 5 | BB29: Nhược điểm | BC29: N06 | BD29: Ít dự án mới, nhà cũ | BE29: =IFERROR(VLOOKUP(BC29,'Master Data'!$BJ$5:$BM$100,4,FALSE),"") -> Ít dự án mới, nhà cũ | BF29: Hạn chế phát triển dự án mới | BG29: =BD29=BE29 -> TRUE | BJ29: N04 | BK29: Nhược điểm | BL29: Tiện ích | BM29: Thiếu tiện ích nội khu, ít khu vui chơi | BN29: --- | BO29: Khu dân cư cũ, chưa phát triển
V30: =IF(W29<>"", IF(ISNUMBER(V29), V29+1, 1), "") | AQ30: =IF(AR29<>"", IF(ISNUMBER(AQ29), AQ29+1, 1), "") | AX30: 26 | AY30: Hồ Chí Minh | AZ30: Vành trong | BA30: Phú Nhuận | BB30: Ưu điểm | BC30: U01 | BD30: Gần trung tâm, di chuyển thuận tiện | BE30: =IFERROR(VLOOKUP(BC30,'Master Data'!$BJ$5:$BM$100,4,FALSE),"") -> Gần trung tâm, di chuyển thuận tiện | BF30: Gần sân bay, Q1, Q3 | BG30: =BD30=BE30 -> TRUE | BJ30: N05 | BK30: Nhược điểm | BL30: Môi trường sống | BM30: Mật độ cao, ít cây xanh, ồn ào | BN30: --- | BO30: Trung tâm hoặc khu lao động đông đúc
AX31: 27 | AY31: Hồ Chí Minh | AZ31: Vành trong | BA31: Phú Nhuận | BB31: Ưu điểm | BC31: U06 | BD31: Khu vực an ninh, dân trí cao | BE31: =IFERROR(VLOOKUP(BC31,'Master Data'!$BJ$5:$BM$100,4,FALSE),"") -> Khu vực an ninh, dân trí cao | BF31: Dân cư ổn định, nhiều khu compound | BG31: =BD31=BE31 -> TRUE | BJ31: N05-1 | BK31: Nhược điểm | BL31: Môi trường sống | BM31: Ô nhiễm tiếng ồn và khói bụi | BN31: --- | BO31: Gần trục đường chính
AX32: 28 | AY32: Hồ Chí Minh | AZ32: Vành trong | BA32: Phú Nhuận | BB32: Nhược điểm | BC32: N03 | BD32: Giá cao, chi phí sinh hoạt đắt đỏ | BE32: =IFERROR(VLOOKUP(BC32,'Master Data'!$BJ$5:$BM$100,4,FALSE),"") -> Giá cao, chi phí sinh hoạt đắt đỏ | BF32: Đắt gần ngang Q3 | BG32: =BD32=BE32 -> TRUE | BJ32: N06 | BK32: Nhược điểm | BL32: Dự án | BM32: Ít dự án mới, nhà cũ | BN32: --- | BO32: Q5, Q10, khu trung tâm cũ
AX33: 29 | AY33: Hồ Chí Minh | AZ33: Khu Nam cao cấp | BA33: Quận 7 | BB33: Ưu điểm | BC33: U02 | BD33: Khu quy hoạch mới, hiện đại | BE33: =IFERROR(VLOOKUP(BC33,'Master Data'!$BJ$5:$BM$100,4,FALSE),"") -> Khu vực quy hoạch mới, hiện đại | BF33: Quy hoạch bài bản, xanh sạch | BG33: =BD33=BE33 -> FALSE | BJ33: N07 | BK33: Nhược điểm | BL33: Vị trí | BM33: Xa trung tâm, di chuyển 30–60 phút | BN33: --- | BO33: Q9, Bình Chánh, Nhà Bè
AX34: 30 | AY34: Hồ Chí Minh | AZ34: Khu Nam cao cấp | BA34: Quận 7 | BB34: Ưu điểm | BC34: U05 | BD34: Đầy đủ tiện ích: trường, bệnh viện, TTTM | BE34: =IFERROR(VLOOKUP(BC34,'Master Data'!$BJ$5:$BM$100,4,FALSE),"") -> Đầy đủ tiện ích: trường, bệnh viện, TTTM | BF34: Có Crescent Mall, FV, trường quốc tế | BG34: =BD34=BE34 -> TRUE | BJ34: N07-1 | BK34: Nhược điểm | BL34: Vị trí | BM34: Kết nối phụ thuộc cầu/đường độc đạo | BN34: --- | BO34: Q7, Q2, Q9 thường kẹt cầu
AX35: 31 | AY35: Hồ Chí Minh | AZ35: Khu Nam cao cấp | BA35: Quận 7 | BB35: Ưu điểm | BC35: U10 | BD35: Có dịch vụ cao cấp, quốc tế | BE35: =IFERROR(VLOOKUP(BC35,'Master Data'!$BJ$5:$BM$100,4,FALSE),"") -> Có trường quốc tế, bệnh viện quốc tế | BF35: Phù hợp người nước ngoài | BG35: =BD35=BE35 -> FALSE | BJ35: N08 | BK35: Nhược điểm | BL35: Quản lý | BM35: Phí quản lý cao (chung cư, khu cao cấp) | BN35: --- | BO35: Khu cao cấp như Q7, Thảo Điền
AX36: 32 | AY36: Hồ Chí Minh | AZ36: Khu Nam cao cấp | BA36: Quận 7 | BB36: Nhược điểm | BC36: N07-1 | BD36: Kết nối phụ thuộc cầu/đường độc đạo | BE36: =IFERROR(VLOOKUP(BC36,'Master Data'!$BJ$5:$BM$100,4,FALSE),"") -> Kết nối phụ thuộc cầu/đường độc đạo | BF36: Dễ kẹt cầu Kênh Tẻ, Nguyễn Văn Linh | BG36: =BD36=BE36 -> TRUE
AX37: 33 | AY37: Hồ Chí Minh | AZ37: Khu Tây – Nam | BA37: Bình Chánh | BB37: Ưu điểm | BC37: U07 | BD37: Giá còn mềm so với trung tâm | BE37: =IFERROR(VLOOKUP(BC37,'Master Data'!$BJ$5:$BM$100,4,FALSE),"") -> Giá còn mềm so với trung tâm | BF37: Quỹ đất lớn, nhiều khu dân cư mới | BG37: =BD37=BE37 -> TRUE
AX38: 34 | AY38: Hồ Chí Minh | AZ38: Khu Tây – Nam | BA38: Bình Chánh | BB38: Ưu điểm | BC38: U02 | BD38: Có khu quy hoạch mới, dân cư tăng | BE38: =IFERROR(VLOOKUP(BC38,'Master Data'!$BJ$5:$BM$100,4,FALSE),"") -> Khu vực quy hoạch mới, hiện đại | BF38: Đang đô thị hóa nhanh | BG38: =BD38=BE38 -> FALSE
AX39: 35 | AY39: Hồ Chí Minh | AZ39: Khu Tây – Nam | BA39: Bình Chánh | BB39: Nhược điểm | BC39: N07 | BD39: Xa trung tâm, di chuyển 30–60 phút | BE39: =IFERROR(VLOOKUP(BC39,'Master Data'!$BJ$5:$BM$100,4,FALSE),"") -> Xa trung tâm, di chuyển 30–60 phút | BF39: Mất 45–60 phút vào Q1 | BG39: =BD39=BE39 -> TRUE
AX40: 36 | AY40: Hồ Chí Minh | AZ40: Khu Tây – Nam | BA40: Bình Chánh | BB40: Nhược điểm | BC40: N02 | BD40: Hạ tầng cũ, một số đường nhỏ | BE40: =IFERROR(VLOOKUP(BC40,'Master Data'!$BJ$5:$BM$100,4,FALSE),"") -> Hạ tầng cũ, đường nhỏ, dễ ngập | BF40: Một số tuyến chưa mở rộng | BG40: =BD40=BE40 -> FALSE
AX41: 37 | AY41: Hồ Chí Minh | AZ41: Khu Tây – Nam | BA41: Quận 8 | BB41: Ưu điểm | BC41: U07 | BD41: Giá còn mềm so với trung tâm | BE41: =IFERROR(VLOOKUP(BC41,'Master Data'!$BJ$5:$BM$100,4,FALSE),"") -> Giá còn mềm so với trung tâm | BF41: Dễ mua để ở thật | BG41: =BD41=BE41 -> TRUE
...
